<?xml version="1.0" encoding="UTF-8"?>
<!-- Generated by org.testng.reporters.JUnitReportReporter -->
<testsuite hostname="TGSI-LAP-21416" failures="1" tests="1" name="part1.LoginShouldFailTest" time="6.063" errors="0" timestamp="2025-05-29T07:56:44 PST" skipped="0">
  <testcase classname="part1.LoginShouldFailTest" name="testLoggingIntoApplication" time="6.063">
    <failure message="did not expect to find [Dashboard] but found [Dashboard]" type="java.lang.AssertionError">
      <![CDATA[java.lang.AssertionError: did not expect to find [Dashboard] but found [Dashboard]
at org.testng.Assert.fail(Assert.java:97)
at org.testng.Assert.assertNotEquals(Assert.java:1401)
at org.testng.Assert.assertNotEquals(Assert.java:1406)
at part1.LoginShouldFailTest.testLoggingIntoApplication(LoginShouldFailTest.java:45)
at java.base/jdk.internal.reflect.DirectMethodHandleAccessor.invoke(DirectMethodHandleAccessor.java:104)
at java.base/java.lang.reflect.Method.invoke(Method.java:565)
at org.testng.internal.MethodInvocationHelper.invokeMethod(MethodInvocationHelper.java:133)
at org.testng.internal.TestInvoker.invokeMethod(TestInvoker.java:584)
at org.testng.internal.TestInvoker.invokeTestMethod(TestInvoker.java:172)
at org.testng.internal.MethodRunner.runInSequence(MethodRunner.java:46)
at org.testng.internal.TestInvoker$MethodInvocationAgent.invoke(TestInvoker.java:804)
at org.testng.internal.TestInvoker.invokeTestMethods(TestInvoker.java:145)
at org.testng.internal.TestMethodWorker.invokeTestMethods(TestMethodWorker.java:146)
at org.testng.internal.TestMethodWorker.run(TestMethodWorker.java:128)
at java.base/java.util.ArrayList.forEach(ArrayList.java:1604)
at org.testng.TestRunner.privateRun(TestRunner.java:770)
at org.testng.TestRunner.run(TestRunner.java:591)
at org.testng.SuiteRunner.runTest(SuiteRunner.java:402)
at org.testng.SuiteRunner.runSequentially(SuiteRunner.java:396)
at org.testng.SuiteRunner.privateRun(SuiteRunner.java:355)
at org.testng.SuiteRunner.run(SuiteRunner.java:304)
at org.testng.SuiteRunnerWorker.runSuite(SuiteRunnerWorker.java:53)
at org.testng.SuiteRunnerWorker.run(SuiteRunnerWorker.java:96)
at org.testng.TestNG.runSuitesSequentially(TestNG.java:1180)
at org.testng.TestNG.runSuitesLocally(TestNG.java:1102)
at org.testng.TestNG.runSuites(TestNG.java:1032)
at org.testng.TestNG.run(TestNG.java:1000)
at org.apache.maven.surefire.testng.TestNGExecutor.run(TestNGExecutor.java:155)
at org.apache.maven.surefire.testng.TestNGDirectoryTestSuite.executeSingleClass(TestNGDirectoryTestSuite.java:102)
at org.apache.maven.surefire.testng.TestNGDirectoryTestSuite.execute(TestNGDirectoryTestSuite.java:91)
at org.apache.maven.surefire.testng.TestNGProvider.invoke(TestNGProvider.java:137)
at org.apache.maven.surefire.booter.ForkedBooter.runSuitesInProcess(ForkedBooter.java:385)
at org.apache.maven.surefire.booter.ForkedBooter.execute(ForkedBooter.java:162)
at org.apache.maven.surefire.booter.ForkedBooter.run(ForkedBooter.java:507)
at org.apache.maven.surefire.booter.ForkedBooter.main(ForkedBooter.java:495)
]]>
    </failure>
  </testcase> <!-- testLoggingIntoApplication -->
</testsuite> <!-- part1.LoginShouldFailTest -->
